2024-09-29 00:32:13,908 INFO    MainThread:12456 [wandb_setup.py:_flush():79] Current SDK version is 0.18.2
2024-09-29 00:32:13,908 INFO    MainThread:12456 [wandb_setup.py:_flush():79] Configure stats pid to 12456
2024-09-29 00:32:13,909 INFO    MainThread:12456 [wandb_setup.py:_flush():79] Loading settings from C:\Users\imane\.config\wandb\settings
2024-09-29 00:32:13,909 INFO    MainThread:12456 [wandb_setup.py:_flush():79] Loading settings from C:\Users\imane\OneDrive\Documents\dynamic_pricing\wandb\settings
2024-09-29 00:32:13,909 INFO    MainThread:12456 [wandb_setup.py:_flush():79] Loading settings from environment variables: {}
2024-09-29 00:32:13,909 INFO    MainThread:12456 [wandb_setup.py:_flush():79] Applying setup settings: {'mode': None, '_disable_service': None}
2024-09-29 00:32:13,909 INFO    MainThread:12456 [wandb_setup.py:_flush():79] Inferring run settings from compute environment: {'program_relpath': 'OneDrive\\Documents\\dynamic_pricing\\src\\main.py', 'program_abspath': 'c:\\Users\\imane\\OneDrive\\Documents\\dynamic_pricing\\src\\main.py', 'program': 'c:\\Users\\imane\\OneDrive\\Documents\\dynamic_pricing\\src\\main.py'}
2024-09-29 00:32:13,909 INFO    MainThread:12456 [wandb_setup.py:_flush():79] Applying login settings: {}
2024-09-29 00:32:13,909 INFO    MainThread:12456 [wandb_init.py:_log_setup():532] Logging user logs to C:\Users\imane\OneDrive\Documents\dynamic_pricing\wandb\run-20240929_003213-kq1pe5up\logs\debug.log
2024-09-29 00:32:13,909 INFO    MainThread:12456 [wandb_init.py:_log_setup():533] Logging internal logs to C:\Users\imane\OneDrive\Documents\dynamic_pricing\wandb\run-20240929_003213-kq1pe5up\logs\debug-internal.log
2024-09-29 00:32:13,909 INFO    MainThread:12456 [wandb_init.py:init():616] calling init triggers
2024-09-29 00:32:13,909 INFO    MainThread:12456 [wandb_init.py:init():623] wandb.init called with sweep_config: {}
config: {'dataset': 'Dynamic Pricing Dataset', 'model': 'Random Forest Regressor', 'test_size': 0.2, 'random_state': 42}
2024-09-29 00:32:13,909 INFO    MainThread:12456 [wandb_init.py:init():666] starting backend
2024-09-29 00:32:13,909 INFO    MainThread:12456 [wandb_init.py:init():670] sending inform_init request
2024-09-29 00:32:13,913 INFO    MainThread:12456 [backend.py:_multiprocessing_setup():104] multiprocessing start_methods=spawn, using: spawn
2024-09-29 00:32:13,914 INFO    MainThread:12456 [wandb_init.py:init():683] backend started and connected
2024-09-29 00:32:13,923 INFO    MainThread:12456 [wandb_init.py:init():778] updated telemetry
2024-09-29 00:32:13,925 INFO    MainThread:12456 [wandb_init.py:init():811] communicating run to backend with 90.0 second timeout
2024-09-29 00:32:14,163 ERROR   MainThread:12456 [wandb_init.py:init():837] encountered error: failed to upsert bucket: returned error 404 Not Found: {"errors":[{"message":"entity your_wandb_username not found during upsertBucket","path":["upsertBucket"]}],"data":{"upsertBucket":null}}
2024-09-29 00:32:14,163 ERROR   MainThread:12456 [wandb_init.py:init():1261] error in wandb.init()
Traceback (most recent call last):
  File "C:\Users\imane\AppData\Local\Programs\Python\Python312\Lib\site-packages\wandb\sdk\wandb_init.py", line 1251, in init
    return wi.init()
           ^^^^^^^^^
  File "C:\Users\imane\AppData\Local\Programs\Python\Python312\Lib\site-packages\wandb\sdk\wandb_init.py", line 843, in init
    raise error
wandb.errors.errors.CommError: failed to upsert bucket: returned error 404 Not Found: {"errors":[{"message":"entity your_wandb_username not found during upsertBucket","path":["upsertBucket"]}],"data":{"upsertBucket":null}}
2024-09-29 00:32:14,512 WARNING MsgRouterThr:12456 [router.py:message_loop():77] message_loop has been closed
